Workbook

Sheet Your Firm Profile
A1: Your Firm Profile
A2: Field Name | B2: Your Value | C2: Units / Notes
A4: BILLING & REVENUE
A5: Average Billing Rate | C5: $/hour
A6: Number of Attorneys | C6: Count
A7: Average Revenue Per Case | C7: $
A8: % of Billable Time Actually Billed | C8: Enter as whole number (e.g. 91 for 91%)
A9: CASELOAD & WORKLOAD
A10: Current Caseload (active cases) | C10: Count
A11: Hours Lost to Admin Per Attorney/Week | C11: Hours (2-10)
A12: MARKETING & INTAKE
A13: New Leads Per Month | C13: Count
A14: Lead Response Time (current) | C14: Hours (1-48)
A15: Lead Conversion Rate (current) | C15: Enter as whole number (e.g. 7 for 7%)
A16: Monthly Marketing Spend | C16: $
A17: OPERATIONS
A18: Weekly "Where's My Case?" Calls | C18: Count (5-30)
A19: Time Spent on Billing/Collections Per Week | C19: Hours (2-15)
A20: Missed Deadlines in Past 12 Months | C20: Count (0-5+)
A22: Instructions: Fill in Column B with your firm's current metrics. Hover over any field for a detailed explanation. Percentages should be entered as whole numbers (e.g. 91 for 91%, 20 for 20%). Use practice-area benchmarks in the Summary tab as a starting point.

Sheet Phase-by-Phase ROI
A1: ROI Calculator: Automated Law Firm Blueprint
A2: Based on inputs from "Your Firm Profile" tab
A3: All projections are estimates based on industry benchmarks and may vary.
A5: PHASE 1: Intake + Deadlines (Month 1)
A6: Metric | B6: Current | C6: Improved | D6: Change | E6: Annual Impact
A7: Lead Conversion Rate | B7: =('Your Firm Profile'!B15/100) | C7: =MIN(('Your Firm Profile'!B15/100)*1.3,0.6)
A8: Conversions Per Month | B8: ='Your Firm Profile'!B13*B7 | C8: ='Your Firm Profile'!B13*C7
A9: New Cases Gained/Month | D9: =C8-B8
A10: Revenue from New Cases/Month | D10: =D9*'Your Firm Profile'!B7 | E10: =D10*12
A11: Missed Deadlines → Zero | B11: ='Your Firm Profile'!B20 | C11: 0
A12: PHASE 1 ANNUAL ROI | E12: =E10
A13: Assumption: 30% conversion improvement (capped at 60%). Faster response captures leads before they call competitors.
A15: PHASE 2: Document Assembly + Billing (Month 2)
A16: Metric | B16: Current | C16: Improved | D16: Change | E16: Annual Impact
A17: Admin Hours Lost/Attorney/Week | B17: ='Your Firm Profile'!B11 | C17: ='Your Firm Profile'!B11*0.35
A18: Hours Recovered/Week (All Attorneys) | D18: =(B17-C17)*'Your Firm Profile'!B6 | E18: =D18*52
A19: Revenue from Recovered Hours | D19: =D18*'Your Firm Profile'!B5 | E19: =D19*52
A20: Billable Capture Rate | B20: =('Your Firm Profile'!B8/100) | C20: =MIN(('Your Firm Profile'!B8/100)+0.15,0.95)
A21: Additional Billed Revenue/Month | D21: =(C20-B20)*('Your Firm Profile'!B10/12)*'Your Firm Profile'!B7 | E21: =D21*12
A22: PHASE 2 ANNUAL ROI | E22: =E19+E21
A23: Assumptions: 65% admin reduction, 15 percentage point billing capture improvement (capped at 95%).
A25: PHASE 3: Client Communication (Month 3)
A26: Metric | B26: Current | C26: Improved | D26: Change | E26: Annual Impact
A27: "Where's My Case?" Calls/Week | B27: ='Your Firm Profile'!B18 | C27: ='Your Firm Profile'!B18*0.2
A28: Calls Eliminated/Week | D28: =B27-C27
A29: Hours Saved from Calls/Week | D29: =D28*12/60
A30: Revenue from Call Time Savings | E30: =D29*'Your Firm Profile'!B5*52
A31: Manual Update Time Saved/Attorney/Week | B31: 2 | C31: 0.4 | D31: =(B31-C31)*'Your Firm Profile'!B6
A32: Revenue from Update Time Savings | E32: =D31*'Your Firm Profile'!B5*52
A33: PHASE 3 ANNUAL ROI | E33: =E30+E32
A34: Assumptions: 80% support call reduction, 12 min/call, 2→0.4 hrs/attorney/week manual updates.
A36: PHASE 4: Marketing Engine (Month 4+)
A37: Metric | B37: Current | C37: Improved | D37: Change | E37: Annual Impact
A38: Cost Per Acquisition (CPA) | B38: =IF(('Your Firm Profile'!B15/100)>0,'Your Firm Profile'!B16/('Your Firm Profile'!B13*('Your Firm Profile'!B15/100)),0) | C38: =B38*0.6
A39: Clients/Month at Current CPA | B39: ='Your Firm Profile'!B13*('Your Firm Profile'!B15/100)
A40: Clients/Month at Improved CPA | C40: =IF(C38>0,'Your Firm Profile'!B16/C38,0)
A41: Additional Clients/Month | D41: =C40-B39
A42: Revenue from Additional Clients | D42: =D41*'Your Firm Profile'!B7 | E42: =D42*12
A43: PHASE 4 ANNUAL ROI | E43: =E42
A44: Assumptions: 40% CPA reduction from attribution tracking and automated follow-up. Marketing spend held constant.
...

Sheet Summary Dashboard
A1: Summary Dashboard
A3: Phase | B3: Annual ROI
A4: Phase 1: Intake + Deadlines | B4: ='Phase-by-Phase ROI'!E12
A5: Phase 2: Document + Billing | B5: ='Phase-by-Phase ROI'!E22
A6: Phase 3: Client Communication | B6: ='Phase-by-Phase ROI'!E33
A7: Phase 4: Marketing Engine | B7: ='Phase-by-Phase ROI'!E43
A9: TOTAL ANNUAL ROI | B9: =SUM(B4:B7)
A10: TOTAL MONTHLY ROI | B10: =B9/12
A12: IMPLEMENTATION INVESTMENT
A13: Scenario | B13: Cost | C13: Annual ROI | D13: Payback (Months) | E13: ROI Multiple
A14: Low-End (DIY + Tools) | B14: 5000 | C14: =B9 | D14: =IF(B9>0,B14/(B9/12),"N/A") | E14: =IF(B14>0,B9/B14,"N/A")
A15: Mid-Range (Partial Custom) | B15: 10000 | C15: =B9 | D15: =IF(B9>0,B15/(B9/12),"N/A") | E15: =IF(B15>0,B9/B15,"N/A")
A16: High-End (Full Custom Build) | B16: 15000 | C16: =B9 | D16: =IF(B9>0,B16/(B9/12),"N/A") | E16: =IF(B16>0,B9/B16,"N/A")
A19: PRACTICE-AREA BENCHMARKS (Copy to Your Firm Profile)
A20: Metric | B20: Bankruptcy | C20: Criminal Defense | D20: Administrative
A21: Billing Rate ($/hr) | B21: 300 | C21: 400 | D21: 350
A22: Attorneys | B22: 2 | C22: 1 | D22: 3
A23: Avg Revenue/Case | B23: 2500 | C23: 5000 | D23: 4000
A24: Billable Capture % | B24: 70 | C24: 65 | D24: 75
A25: Caseload | B25: 35 | C25: 25 | D25: 30
A26: Admin Hrs Lost/Atty/Wk | B26: 7 | C26: 8 | D26: 6
A27: Leads/Month | B27: 25 | C27: 18 | D27: 15
A28: Response Time (hrs) | B28: 36 | C28: 48 | D28: 24
A29: Conversion Rate % | B29: 13 | C29: 5 | D29: 8
A30: Marketing Spend/Mo | B30: 1500 | C30: 2500 | D30: 1800
A31: Support Calls/Wk | B31: 18 | C31: 15 | D31: 12
A32: Billing Hrs/Wk | B32: 8 | C32: 6 | D32: 5
A33: Missed Deadlines/Yr | B33: 2 | C33: 1 | D33: 1
A35: Note: Percentages are whole numbers (70 = 70%, 22 = 22%). Enter them exactly as shown into Your Firm Profile.
A37: Disclaimer: All projections are estimates. Not financial, legal, or business advice. The Innovative Native LLC makes no warranties regarding accuracy. Consult qualified professionals.
A38: © 2026 The Innovative Native LLC
